Workbook

Sheet Detail5-4214658
A1: current_tier | B1: month | C1: initiated_by_org_id | D1: activation_month | E1: total_payments | F1: ach_payments | G1: tpv | H1: total_revenue | I1: ach_fees | J1: core_gross_profit_wo_loss | K1: core_gp | L1: loss | M1: sub_gp | N1: Total GP | O1: Opp Create Date | P1: Opp Create Month | Q1: Count GP?
A2: Melio Basic | B2: 46023 | C2: 4214658 | D2: 45962 | E2: 67 | F2: 67 | G2: 141628.32 | H2: 0 | J2: -9.8331 | K2: -9.8331 | L2: 0 | N2: -9.8331 | O2: 45973 | P2: 45962 | Q2: Yes

Sheet Detail4-4117067
A1: current_tier | B1: month | C1: initiated_by_org_id | D1: activation_month | E1: total_payments | F1: ach_payments | G1: tpv | H1: total_revenue | I1: ach_fees | J1: core_gross_profit_wo_loss | K1: core_gp | L1: loss | M1: sub_gp | N1: Total GP | O1: Opp Create Date | P1: Opp Create Month | Q1: Count GP?
A2: Melio Unlimited Ach | B2: 46023 | C2: 4117067 | D2: 45992 | E2: 575 | F2: 575 | G2: 2880932.6 | H2: 1057.7422 | I2: 0.5 | J2: 973.2603 | K2: 973.2603 | L2: 0 | M2: 6.4 | N2: 979.6603 | O2: 45831 | P2: 45809 | Q2: Yes

Sheet Current Calendar Quarter Stats
G1: AP Status | H1: AR Status | I1: AP/AR Status | J1: Opportunity Owner | K1: Account Name | L1: Estimated Monthly GP | M1: Expected Ramp Complete Month | N1: Close Date | O1: Total Orgs | P1: =COUNTIF(A2:A1000,">=0") -> 168 | R1: LAST DATA PULL: | S1: 46201 | U1: Ramp Start Date
G2: {=iferror(XLOOKUP(A2,'Download of SFDC Activation Rep'!B:B,'Download of SFDC Activation Rep'!H:H),"")} -> Active | H2: {=iferror(xlookup(A2,'Download of SFDC Activation Rep'!B:B,'Download of SFDC Activation Rep'!L:L),"")} | I2: =IF(or(G2="Active",H2="Active"),"Active","Not Active") -> Active | J2: {=iferror(XLOOKUP(A2,'Download of SFDC Activation Rep'!B:B,'Download of SFDC Activation Rep'!X:X),"")} -> Kate Olivares | K2: {=iferror(XLOOKUP(A2,'Download of SFDC Activation Rep'!B:B,'Download of SFDC Activation Rep'!C:C),"")} -> Net Conversion | L2: {=iferror(XLOOKUP(A2,'Download of SFDC Activation Rep'!B:B,'Download of SFDC Activation Rep'!S:S),"")} -> 400 | M2: {=iferror(XLOOKUP(A2,'Download of SFDC Activation Rep'!B:B,'Download of SFDC Activation Rep'!Z:Z)+150,"")} -> 45981 | N2: {=iferror(XLOOKUP(A2,'Download of SFDC Activation Rep'!B:B,'Download of SFDC Activation Rep'!Y:Y),"")} -> 45992 | O2: Total Active Orgs | P2: =COUNTIF(I:I,"Active") -> 148 | U2: =IF(M2="", "", EOMONTH(M2, -5) + 1) -> 45839
G3: {=iferror(XLOOKUP(A3,'Download of SFDC Activation Rep'!B:B,'Download of SFDC Activation Rep'!H:H),"")} -> Active | H3: {=iferror(xlookup(A3,'Download of SFDC Activation Rep'!B:B,'Download of SFDC Activation Rep'!L:L),"")} | I3: =IF(or(G3="Active",H3="Active"),"Active","Not Active") -> Active | J3: {=iferror(XLOOKUP(A3,'Download of SFDC Activation Rep'!B:B,'Download of SFDC Activation Rep'!X:X),"")} -> Matthew Frost | K3: {=iferror(XLOOKUP(A3,'Download of SFDC Activation Rep'!B:B,'Download of SFDC Activation Rep'!C:C),"")} -> Solutions Group International, Inc. | L3: {=iferror(XLOOKUP(A3,'Download of SFDC Activation Rep'!B:B,'Download of SFDC Activation Rep'!S:S),"")} -> 155.65 | M3: {=iferror(XLOOKUP(A3,'Download of SFDC Activation Rep'!B:B,'Download of SFDC Activation Rep'!Z:Z)+150,"")} -> 46178 | N3: {=iferror(XLOOKUP(A3,'Download of SFDC Activation Rep'!B:B,'Download of SFDC Activation Rep'!Y:Y),"")} -> 46079 | Q3: =(TODAY() - EOMONTH(TODAY(), -MOD(MONTH(TODAY())-1,3)-1)) / (EOMONTH(TODAY(), -MOD(MONTH(TODAY())-1,3)+2)+1 - (EOMONTH(TODAY(), -MOD(MONTH(TODAY())-1,3)-1)+1)) -> 0.98901099 | R3: of way through quarter | U3: =IF(M3="", "", EOMONTH(M3, -5) + 1) -> 46054
G4: {=iferror(XLOOKUP(A4,'Download of SFDC Activation Rep'!B:B,'Download of SFDC Activation Rep'!H:H),"")} -> Active | H4: {=iferror(xlookup(A4,'Download of SFDC Activation Rep'!B:B,'Download of SFDC Activation Rep'!L:L),"")} | I4: =IF(or(G4="Active",H4="Active"),"Active","Not Active") -> Active | J4: {=iferror(XLOOKUP(A4,'Download of SFDC Activation Rep'!B:B,'Download of SFDC Activation Rep'!X:X),"")} -> Matthew Frost | K4: {=iferror(XLOOKUP(A4,'Download of SFDC Activation Rep'!B:B,'Download of SFDC Activation Rep'!C:C),"")} -> National Rural Health Association | L4: {=iferror(XLOOKUP(A4,'Download of SFDC Activation Rep'!B:B,'Download of SFDC Activation Rep'!S:S),"")} -> 128.1 | M4: {=iferror(XLOOKUP(A4,'Download of SFDC Activation Rep'!B:B,'Download of SFDC Activation Rep'!Z:Z)+150,"")} -> 46111 | N4: {=iferror(XLOOKUP(A4,'Download of SFDC Activation Rep'!B:B,'Download of SFDC Activation Rep'!Y:Y),"")} -> 46013 | O4: Avg Monthly TPV for Group | P4: =P15/(3*Q3) -> 18436255 | Q4: =(TODAY() - EOMONTH(TODAY(), -MOD(MONTH(TODAY())-1,3)-1)) / (EOMONTH(TODAY(), -MOD(MONTH(TODAY())-1,3)+2)+1 - (EOMONTH(TODAY(), -MOD(MONTH(TODAY())-1,3)-1)+1)) -> 0.98901099 | U4: =IF(M4="", "", EOMONTH(M4, -5) + 1) -> 45962
G5: {=iferror(XLOOKUP(A5,'Download of SFDC Activation Rep'!B:B,'Download of SFDC Activation Rep'!H:H),"")} -> Active | H5: {=iferror(xlookup(A5,'Download of SFDC Activation Rep'!B:B,'Download of SFDC Activation Rep'!L:L),"")} | I5: =IF(or(G5="Active",H5="Active"),"Active","Not Active") -> Active | J5: {=iferror(XLOOKUP(A5,'Download of SFDC Activation Rep'!B:B,'Download of SFDC Activation Rep'!X:X),"")} -> Arianna Modesti | K5: {=iferror(XLOOKUP(A5,'Download of SFDC Activation Rep'!B:B,'Download of SFDC Activation Rep'!C:C),"")} -> HTT Cardmax Company | L5: {=iferror(XLOOKUP(A5,'Download of SFDC Activation Rep'!B:B,'Download of SFDC Activation Rep'!S:S),"")} -> 671.95 | M5: {=iferror(XLOOKUP(A5,'Download of SFDC Activation Rep'!B:B,'Download of SFDC Activation Rep'!Z:Z)+150,"")} -> 46347 | N5: {=iferror(XLOOKUP(A5,'Download of SFDC Activation Rep'!B:B,'Download of SFDC Activation Rep'!Y:Y),"")} -> 46361 | O5: Avg Monthly GP for Group | P5: =P13/(3*Q3) -> 24284.269 | U5: =IF(M5="", "", EOMONTH(M5, -5) + 1) -> 46204
G6: {=iferror(XLOOKUP(A6,'Download of SFDC Activation Rep'!B:B,'Download of SFDC Activation Rep'!H:H),"")} -> Active | H6: {=iferror(xlookup(A6,'Download of SFDC Activation Rep'!B:B,'Download of SFDC Activation Rep'!L:L),"")} | I6: =IF(or(G6="Active",H6="Active"),"Active","Not Active") -> Active | J6: {=iferror(XLOOKUP(A6,'Download of SFDC Activation Rep'!B:B,'Download of SFDC Activation Rep'!X:X),"")} -> Matthew Frost | K6: {=iferror(XLOOKUP(A6,'Download of SFDC Activation Rep'!B:B,'Download of SFDC Activation Rep'!C:C),"")} -> Toland Construction - MO | L6: {=iferror(XLOOKUP(A6,'Download of SFDC Activation Rep'!B:B,'Download of SFDC Activation Rep'!S:S),"")} -> 287 | M6: {=iferror(XLOOKUP(A6,'Download of SFDC Activation Rep'!B:B,'Download of SFDC Activation Rep'!Z:Z)+150,"")} -> 46031 | N6: {=iferror(XLOOKUP(A6,'Download of SFDC Activation Rep'!B:B,'Download of SFDC Activation Rep'!Y:Y),"")} -> 45889 | U6: =IF(M6="", "", EOMONTH(M6, -5) + 1) -> 45901
G7: {=iferror(XLOOKUP(A7,'Download of SFDC Activation Rep'!B:B,'Download of SFDC Activation Rep'!H:H),"")} -> Active | H7: {=iferror(xlookup(A7,'Download of SFDC Activation Rep'!B:B,'Download of SFDC Activation Rep'!L:L),"")} | I7: =IF(or(G7="Active",H7="Active"),"Active","Not Active") -> Active | J7: {=iferror(XLOOKUP(A7,'Download of SFDC Activation Rep'!B:B,'Download of SFDC Activation Rep'!X:X),"")} -> Arianna Modesti | K7: {=iferror(XLOOKUP(A7,'Download of SFDC Activation Rep'!B:B,'Download of SFDC Activation Rep'!C:C),"")} -> DataLinks LLC | L7: {=iferror(XLOOKUP(A7,'Download of SFDC Activation Rep'!B:B,'Download of SFDC Activation Rep'!S:S),"")} -> 315.9 | M7: {=iferror(XLOOKUP(A7,'Download of SFDC Activation Rep'!B:B,'Download of SFDC Activation Rep'!Z:Z)+150,"")} -> 46320 | N7: {=iferror(XLOOKUP(A7,'Download of SFDC Activation Rep'!B:B,'Download of SFDC Activation Rep'!Y:Y),"")} -> 46258 | O7: Avg Monthly GP per Org | P7: =(P13/P1)/(3*Q3) -> 144.54922 | U7: =IF(M7="", "", EOMONTH(M7, -5) + 1) -> 46174
G8: {=iferror(XLOOKUP(A8,'Download of SFDC Activation Rep'!B:B,'Download of SFDC Activation Rep'!H:H),"")} -> Active | H8: {=iferror(xlookup(A8,'Download of SFDC Activation Rep'!B:B,'Download of SFDC Activation Rep'!L:L),"")} | I8: =IF(or(G8="Active",H8="Active"),"Active","Not Active") -> Active | J8: {=iferror(XLOOKUP(A8,'Download of SFDC Activation Rep'!B:B,'Download of SFDC Activation Rep'!X:X),"")} -> Matthew Frost | K8: {=iferror(XLOOKUP(A8,'Download of SFDC Activation Rep'!B:B,'Download of SFDC Activation Rep'!C:C),"")} -> Hendersonville Community Co-Op | L8: {=iferror(XLOOKUP(A8,'Download of SFDC Activation Rep'!B:B,'Download of SFDC Activation Rep'!S:S),"")} -> 171 | M8: {=iferror(XLOOKUP(A8,'Download of SFDC Activation Rep'!B:B,'Download of SFDC Activation Rep'!Z:Z)+150,"")} -> 46041 | N8: {=iferror(XLOOKUP(A8,'Download of SFDC Activation Rep'!B:B,'Download of SFDC Activation Rep'!Y:Y),"")} -> 46029 | U8: =IF(M8="", "", EOMONTH(M8, -5) + 1) -> 45901
G9: {=iferror(XLOOKUP(A9,'Download of SFDC Activation Rep'!B:B,'Download of SFDC Activation Rep'!H:H),"")} -> Active | H9: {=iferror(xlookup(A9,'Download of SFDC Activation Rep'!B:B,'Download of SFDC Activation Rep'!L:L),"")} | I9: =IF(or(G9="Active",H9="Active"),"Active","Not Active") -> Active | J9: {=iferror(XLOOKUP(A9,'Download of SFDC Activation Rep'!B:B,'Download of SFDC Activation Rep'!X:X),"")} -> Kate Olivares | K9: {=iferror(XLOOKUP(A9,'Download of SFDC Activation Rep'!B:B,'Download of SFDC Activation Rep'!C:C),"")} -> Expert Semiconductor Technology, inc | L9: {=iferror(XLOOKUP(A9,'Download of SFDC Activation Rep'!B:B,'Download of SFDC Activation Rep'!S:S),"")} -> 292.51 | M9: {=iferror(XLOOKUP(A9,'Download of SFDC Activation Rep'!B:B,'Download of SFDC Activation Rep'!Z:Z)+150,"")} -> 45968 | N9: {=iferror(XLOOKUP(A9,'Download of SFDC Activation Rep'!B:B,'Download of SFDC Activation Rep'!Y:Y),"")} -> 45859 | O9: Avg TPV per Org per Month | P9: =P15/P1/(3*Q3) -> 109739.61 | U9: =IF(M9="", "", EOMONTH(M9, -5) + 1) -> 45839
G10: {=iferror(XLOOKUP(A10,'Download of SFDC Activation Rep'!B:B,'Download of SFDC Activation Rep'!H:H),"")} -> Active | H10: {=iferror(xlookup(A10,'Download of SFDC Activation Rep'!B:B,'Download of SFDC Activation Rep'!L:L),"")} | I10: =IF(or(G10="Active",H10="Active"),"Active","Not Active") -> Active | J10: {=iferror(XLOOKUP(A10,'Download of SFDC Activation Rep'!B:B,'Download of SFDC Activation Rep'!X:X),"")} -> Rudy Maestas | K10: {=iferror(XLOOKUP(A10,'Download of SFDC Activation Rep'!B:B,'Download of SFDC Activation Rep'!C:C),"")} -> megg mining llc | L10: {=iferror(XLOOKUP(A10,'Download of SFDC Activation Rep'!B:B,'Download of SFDC Activation Rep'!S:S),"")} -> 665 | M10: {=iferror(XLOOKUP(A10,'Download of SFDC Activation Rep'!B:B,'Download of SFDC Activation Rep'!Z:Z)+150,"")} -> 46074 | N10: {=iferror(XLOOKUP(A10,'Download of SFDC Activation Rep'!B:B,'Download of SFDC Activation Rep'!Y:Y),"")} -> 46055 | U10: =IF(M10="", "", EOMONTH(M10, -5) + 1) -> 45931
G11: {=iferror(XLOOKUP(A11,'Download of SFDC Activation Rep'!B:B,'Download of SFDC Activation Rep'!H:H),"")} -> Active | H11: {=iferror(xlookup(A11,'Download of SFDC Activation Rep'!B:B,'Download of SFDC Activation Rep'!L:L),"")} -> Active | I11: =IF(or(G11="Active",H11="Active"),"Active","Not Active") -> Active | J11: {=iferror(XLOOKUP(A11,'Download of SFDC Activation Rep'!B:B,'Download of SFDC Activation Rep'!X:X),"")} -> Matthew Frost | K11: {=iferror(XLOOKUP(A11,'Download of SFDC Activation Rep'!B:B,'Download of SFDC Activation Rep'!C:C),"")} -> Scale Foundations Inc. | L11: {=iferror(XLOOKUP(A11,'Download of SFDC Activation Rep'!B:B,'Download of SFDC Activation Rep'!S:S),"")} -> 312.17 | M11: {=iferror(XLOOKUP(A11,'Download of SFDC Activation Rep'!B:B,'Download of SFDC Activation Rep'!Z:Z)+150,"")} -> 46178 | N11: {=iferror(XLOOKUP(A11,'Download of SFDC Activation Rep'!B:B,'Download of SFDC Activation Rep'!Y:Y),"")} -> 46086 | U11: =IF(M11="", "", EOMONTH(M11, -5) + 1) -> 46054
G12: {=iferror(XLOOKUP(A12,'Download of SFDC Activation Rep'!B:B,'Download of SFDC Activation Rep'!H:H),"")} -> Active | H12: {=iferror(xlookup(A12,'Download of SFDC Activation Rep'!B:B,'Download of SFDC Activation Rep'!L:L),"")} | I12: =IF(or(G12="Active",H12="Active"),"Active","Not Active") -> Active | J12: {=iferror(XLOOKUP(A12,'Download of SFDC Activation Rep'!B:B,'Download of SFDC Activation Rep'!X:X),"")} -> Arianna Modesti | K12: {=iferror(XLOOKUP(A12,'Download of SFDC Activation Rep'!B:B,'Download of SFDC Activation Rep'!C:C),"")} -> Kloris LLC | L12: {=iferror(XLOOKUP(A12,'Download of SFDC Activation Rep'!B:B,'Download of SFDC Activation Rep'!S:S),"")} -> 385 | M12: {=iferror(XLOOKUP(A12,'Download of SFDC Activation Rep'!B:B,'Download of SFDC Activation Rep'!Z:Z)+150,"")} -> 46286 | N12: {=iferror(XLOOKUP(A12,'Download of SFDC Activation Rep'!B:B,'Download of SFDC Activation Rep'!Y:Y),"")} -> 46244 | U12: =IF(M12="", "", EOMONTH(M12, -5) + 1) -> 46143
G13: {=iferror(XLOOKUP(A13,'Download of SFDC Activation Rep'!B:B,'Download of SFDC Activation Rep'!H:H),"")} -> Active | H13: {=iferror(xlookup(A13,'Download of SFDC Activation Rep'!B:B,'Download of SFDC Activation Rep'!L:L),"")} | I13: =IF(or(G13="Active",H13="Active"),"Active","Not Active") -> Active | J13: {=iferror(XLOOKUP(A13,'Download of SFDC Activation Rep'!B:B,'Download of SFDC Activation Rep'!X:X),"")} -> Kate Olivares | K13: {=iferror(XLOOKUP(A13,'Download of SFDC Activation Rep'!B:B,'Download of SFDC Activation Rep'!C:C),"")} -> Liberty Land Management LLC | L13: {=iferror(XLOOKUP(A13,'Download of SFDC Activation Rep'!B:B,'Download of SFDC Activation Rep'!S:S),"")} -> 0 | M13: {=iferror(XLOOKUP(A13,'Download of SFDC Activation Rep'!B:B,'Download of SFDC Activation Rep'!Z:Z)+150,"")} -> 46124 | N13: {=iferror(XLOOKUP(A13,'Download of SFDC Activation Rep'!B:B,'Download of SFDC Activation Rep'!Y:Y),"")} -> 45933 | O13: Total GP Generated | P13: =SUM(B:B) -> 72052.227 | U13: =IF(M13="", "", EOMONTH(M13, -5) + 1) -> 45992
G14: {=iferror(XLOOKUP(A14,'Download of SFDC Activation Rep'!B:B,'Download of SFDC Activation Rep'!H:H),"")} -> Active | H14: {=iferror(xlookup(A14,'Download of SFDC Activation Rep'!B:B,'Download of SFDC Activation Rep'!L:L),"")} | I14: =IF(or(G14="Active",H14="Active"),"Active","Not Active") -> Active | J14: {=iferror(XLOOKUP(A14,'Download of SFDC Activation Rep'!B:B,'Download of SFDC Activation Rep'!X:X),"")} -> Kate Olivares | K14: {=iferror(XLOOKUP(A14,'Download of SFDC Activation Rep'!B:B,'Download of SFDC Activation Rep'!C:C),"")} -> United Home Care LLC | L14: {=iferror(XLOOKUP(A14,'Download of SFDC Activation Rep'!B:B,'Download of SFDC Activation Rep'!S:S),"")} -> 96.47 | M14: {=iferror(XLOOKUP(A14,'Download of SFDC Activation Rep'!B:B,'Download of SFDC Activation Rep'!Z:Z)+150,"")} -> 45989 | N14: {=iferror(XLOOKUP(A14,'Download of SFDC Activation Rep'!B:B,'Download of SFDC Activation Rep'!Y:Y),"")} -> 45841 | U14: =IF(M14="", "", EOMONTH(M14, -5) + 1) -> 45839
G15: {=iferror(XLOOKUP(A15,'Download of SFDC Activation Rep'!B:B,'Download of SFDC Activation Rep'!H:H),"")} -> Active | H15: {=iferror(xlookup(A15,'Download of SFDC Activation Rep'!B:B,'Download of SFDC Activation Rep'!L:L),"")} | I15: =IF(or(G15="Active",H15="Active"),"Active","Not Active") -> Active | J15: {=iferror(XLOOKUP(A15,'Download of SFDC Activation Rep'!B:B,'Download of SFDC Activation Rep'!X:X),"")} -> Arianna Modesti | K15: {=iferror(XLOOKUP(A15,'Download of SFDC Activation Rep'!B:B,'Download of SFDC Activation Rep'!C:C),"")} -> Naz Apparel | L15: {=iferror(XLOOKUP(A15,'Download of SFDC Activation Rep'!B:B,'Download of SFDC Activation Rep'!S:S),"")} -> 452.7 | M15: {=iferror(XLOOKUP(A15,'Download of SFDC Activation Rep'!B:B,'Download of SFDC Activation Rep'!Z:Z)+150,"")} -> 46347 | N15: {=iferror(XLOOKUP(A15,'Download of SFDC Activation Rep'!B:B,'Download of SFDC Activation Rep'!Y:Y),"")} -> 46361 | O15: Total TPV Generated | P15: =SUM(D:D) -> 54700977 | U15: =IF(M15="", "", EOMONTH(M15, -5) + 1) -> 46204
G16: {=iferror(XLOOKUP(A16,'Download of SFDC Activation Rep'!B:B,'Download of SFDC Activation Rep'!H:H),"")} -> Active | H16: {=iferror(xlookup(A16,'Download of SFDC Activation Rep'!B:B,'Download of SFDC Activation Rep'!L:L),"")} | I16: =IF(or(G16="Active",H16="Active"),"Active","Not Active") -> Active | J16: {=iferror(XLOOKUP(A16,'Download of SFDC Activation Rep'!B:B,'Download of SFDC Activation Rep'!X:X),"")} -> Kate Olivares | K16: {=iferror(XLOOKUP(A16,'Download of SFDC Activation Rep'!B:B,'Download of SFDC Activation Rep'!C:C),"")} -> CDT Construction | L16: {=iferror(XLOOKUP(A16,'Download of SFDC Activation Rep'!B:B,'Download of SFDC Activation Rep'!S:S),"")} -> 338.01 | M16: {=iferror(XLOOKUP(A16,'Download of SFDC Activation Rep'!B:B,'Download of SFDC Activation Rep'!Z:Z)+150,"")} -> 45989 | N16: {=iferror(XLOOKUP(A16,'Download of SFDC Activation Rep'!B:B,'Download of SFDC Activation Rep'!Y:Y),"")} -> 45877 | U16: =IF(M16="", "", EOMONTH(M16, -5) + 1) -> 45839
G17: {=iferror(XLOOKUP(A17,'Download of SFDC Activation Rep'!B:B,'Download of SFDC Activation Rep'!H:H),"")} -> Active | H17: {=iferror(xlookup(A17,'Download of SFDC Activation Rep'!B:B,'Download of SFDC Activation Rep'!L:L),"")} | I17: =IF(or(G17="Active",H17="Active"),"Active","Not Active") -> Active | J17: {=iferror(XLOOKUP(A17,'Download of SFDC Activation Rep'!B:B,'Download of SFDC Activation Rep'!X:X),"")} -> Matthew Frost | K17: {=iferror(XLOOKUP(A17,'Download of SFDC Activation Rep'!B:B,'Download of SFDC Activation Rep'!C:C),"")} -> Kenneth Adam Designs | L17: {=iferror(XLOOKUP(A17,'Download of SFDC Activation Rep'!B:B,'Download of SFDC Activation Rep'!S:S),"")} -> 435 | M17: {=iferror(XLOOKUP(A17,'Download of SFDC Activation Rep'!B:B,'Download of SFDC Activation Rep'!Z:Z)+150,"")} -> 46177 | N17: {=iferror(XLOOKUP(A17,'Download of SFDC Activation Rep'!B:B,'Download of SFDC Activation Rep'!Y:Y),"")} -> 46043 | U17: =IF(M17="", "", EOMONTH(M17, -5) + 1) -> 46054
G18: {=iferror(XLOOKUP(A18,'Download of SFDC Activation Rep'!B:B,'Download of SFDC Activation Rep'!H:H),"")} -> Active | H18: {=iferror(xlookup(A18,'Download of SFDC Activation Rep'!B:B,'Download of SFDC Activation Rep'!L:L),"")} | I18: =IF(or(G18="Active",H18="Active"),"Active","Not Active") -> Active | J18: {=iferror(XLOOKUP(A18,'Download of SFDC Activation Rep'!B:B,'Download of SFDC Activation Rep'!X:X),"")} -> Matthew Frost | K18: {=iferror(XLOOKUP(A18,'Download of SFDC Activation Rep'!B:B,'Download of SFDC Activation Rep'!C:C),"")} -> St George Spirits | L18: {=iferror(XLOOKUP(A18,'Download of SFDC Activation Rep'!B:B,'Download of SFDC Activation Rep'!S:S),"")} -> 280.89 | M18: {=iferror(XLOOKUP(A18,'Download of SFDC Activation Rep'!B:B,'Download of SFDC Activation Rep'!Z:Z)+150,"")} -> 46208 | N18: {=iferror(XLOOKUP(A18,'Download of SFDC Activation Rep'!B:B,'Download of SFDC Activation Rep'!Y:Y),"")} -> 46118 | O18: Median TPV per Org per Month | P18: =MEDIAN(E2:E1000) -> 23535.252 | U18: =IF(M18="", "", EOMONTH(M18, -5) + 1) -> 46082
G19: {=iferror(XLOOKUP(A19,'Download of SFDC Activation Rep'!B:B,'Download of SFDC Activation Rep'!H:H),"")} -> Active | H19: {=iferror(xlookup(A19,'Download of SFDC Activation Rep'!B:B,'Download of SFDC Activation Rep'!L:L),"")} | I19: =IF(or(G19="Active",H19="Active"),"Active","Not Active") -> Active | J19: {=iferror(XLOOKUP(A19,'Download of SFDC Activation Rep'!B:B,'Download of SFDC Activation Rep'!X:X),"")} -> Matthew Frost | K19: {=iferror(XLOOKUP(A19,'Download of SFDC Activation Rep'!B:B,'Download of SFDC Activation Rep'!C:C),"")} -> Abecca Grace, LLC | L19: {=iferror(XLOOKUP(A19,'Download of SFDC Activation Rep'!B:B,'Download of SFDC Activation Rep'!S:S),"")} -> 0 | M19: {=iferror(XLOOKUP(A19,'Download of SFDC Activation Rep'!B:B,'Download of SFDC Activation Rep'!Z:Z)+150,"")} -> 46248 | N19: {=iferror(XLOOKUP(A19,'Download of SFDC Activation Rep'!B:B,'Download of SFDC Activation Rep'!Y:Y),"")} -> 46141 | O19: Median Monthly GP per Org | P19: =MEDIAN(C2:C1000) -> 56.9073 | U19: =IF(M19="", "", EOMONTH(M19, -5) + 1) -> 46113
G20: {=iferror(XLOOKUP(A20,'Download of SFDC Activation Rep'!B:B,'Download of SFDC Activation Rep'!H:H),"")} -> Active | H20: {=iferror(xlookup(A20,'Download of SFDC Activation Rep'!B:B,'Download of SFDC Activation Rep'!L:L),"")} | I20: =IF(or(G20="Active",H20="Active"),"Active","Not Active") -> Active | J20: {=iferror(XLOOKUP(A20,'Download of SFDC Activation Rep'!B:B,'Download of SFDC Activation Rep'!X:X),"")} -> Matthew Frost | K20: {=iferror(XLOOKUP(A20,'Download of SFDC Activation Rep'!B:B,'Download of SFDC Activation Rep'!C:C),"")} -> MJDII Architects, Inc. | L20: {=iferror(XLOOKUP(A20,'Download of SFDC Activation Rep'!B:B,'Download of SFDC Activation Rep'!S:S),"")} -> 72.7 | M20: {=iferror(XLOOKUP(A20,'Download of SFDC Activation Rep'!B:B,'Download of SFDC Activation Rep'!Z:Z)+150,"")} -> 46157 | N20: {=iferror(XLOOKUP(A20,'Download of SFDC Activation Rep'!B:B,'Download of SFDC Activation Rep'!Y:Y),"")} -> 46007 | U20: =IF(M20="", "", EOMONTH(M20, -5) + 1) -> 46023
G21: {=iferror(XLOOKUP(A21,'Download of SFDC Activation Rep'!B:B,'Download of SFDC Activation Rep'!H:H),"")} -> Active | H21: {=iferror(xlookup(A21,'Download of SFDC Activation Rep'!B:B,'Download of SFDC Activation Rep'!L:L),"")} | I21: =IF(or(G21="Active",H21="Active"),"Active","Not Active") -> Active | J21: {=iferror(XLOOKUP(A21,'Download of SFDC Activation Rep'!B:B,'Download of SFDC Activation Rep'!X:X),"")} -> Arianna Modesti | K21: {=iferror(XLOOKUP(A21,'Download of SFDC Activation Rep'!B:B,'Download of SFDC Activation Rep'!C:C),"")} -> Brian Schmidt Builder | L21: {=iferror(XLOOKUP(A21,'Download of SFDC Activation Rep'!B:B,'Download of SFDC Activation Rep'!S:S),"")} -> 316.95 | M21: {=iferror(XLOOKUP(A21,'Download of SFDC Activation Rep'!B:B,'Download of SFDC Activation Rep'!Z:Z)+150,"")} -> 46242 | N21: {=iferror(XLOOKUP(A21,'Download of SFDC Activation Rep'!B:B,'Download of SFDC Activation Rep'!Y:Y),"")} -> 46132 | U21: =IF(M21="", "", EOMONTH(M21, -5) + 1) -> 46113
G22: {=iferror(XLOOKUP(A22,'Download of SFDC Activation Rep'!B:B,'Download of SFDC Activation Rep'!H:H),"")} -> Active | H22: {=iferror(xlookup(A22,'Download of SFDC Activation Rep'!B:B,'Download of SFDC Activation Rep'!L:L),"")} | I22: =IF(or(G22="Active",H22="Active"),"Active","Not Active") -> Active | J22: {=iferror(XLOOKUP(A22,'Download of SFDC Activation Rep'!B:B,'Download of SFDC Activation Rep'!X:X),"")} -> Arianna Modesti | K22: {=iferror(XLOOKUP(A22,'Download of SFDC Activation Rep'!B:B,'Download of SFDC Activation Rep'!C:C),"")} -> Landa Cleary Travel Co. Inc. D.B.A. Mater Dei Tours | L22: {=iferror(XLOOKUP(A22,'Download of SFDC Activation Rep'!B:B,'Download of SFDC Activation Rep'!S:S),"")} -> 281.77 | M22: {=iferror(XLOOKUP(A22,'Download of SFDC Activation Rep'!B:B,'Download of SFDC Activation Rep'!Z:Z)+150,"")} -> 46263 | N22: {=iferror(XLOOKUP(A22,'Download of SFDC Activation Rep'!B:B,'Download of SFDC Activation Rep'!Y:Y),"")} -> 46237 | U22: =IF(M22="", "", EOMONTH(M22, -5) + 1) -> 46113
G23: {=iferror(XLOOKUP(A23,'Download of SFDC Activation Rep'!B:B,'Download of SFDC Activation Rep'!H:H),"")} -> Active | H23: {=iferror(xlookup(A23,'Download of SFDC Activation Rep'!B:B,'Download of SFDC Activation Rep'!L:L),"")} | I23: =IF(or(G23="Active",H23="Active"),"Active","Not Active") -> Active | J23: {=iferror(XLOOKUP(A23,'Download of SFDC Activation Rep'!B:B,'Download of SFDC Activation Rep'!X:X),"")} -> Kate Olivares | K23: {=iferror(XLOOKUP(A23,'Download of SFDC Activation Rep'!B:B,'Download of SFDC Activation Rep'!C:C),"")} -> H&H Auto Parts LLC | L23: {=iferror(XLOOKUP(A23,'Download of SFDC Activation Rep'!B:B,'Download of SFDC Activation Rep'!S:S),"")} -> 423.9 | M23: {=iferror(XLOOKUP(A23,'Download of SFDC Activation Rep'!B:B,'Download of SFDC Activation Rep'!Z:Z)+150,"")} -> 46111 | N23: {=iferror(XLOOKUP(A23,'Download of SFDC Activation Rep'!B:B,'Download of SFDC Activation Rep'!Y:Y),"")} -> 46013 | U23: =IF(M23="", "", EOMONTH(M23, -5) + 1) -> 45962
G24: {=iferror(XLOOKUP(A24,'Download of SFDC Activation Rep'!B:B,'Download of SFDC Activation Rep'!H:H),"")} -> Active | H24: {=iferror(xlookup(A24,'Download of SFDC Activation Rep'!B:B,'Download of SFDC Activation Rep'!L:L),"")} | I24: =IF(or(G24="Active",H24="Active"),"Active","Not Active") -> Active | J24: {=iferror(XLOOKUP(A24,'Download of SFDC Activation Rep'!B:B,'Download of SFDC Activation Rep'!X:X),"")} -> Matthew Frost | K24: {=iferror(XLOOKUP(A24,'Download of SFDC Activation Rep'!B:B,'Download of SFDC Activation Rep'!C:C),"")} -> Shree Satya Sai LLC | L24: {=iferror(XLOOKUP(A24,'Download of SFDC Activation Rep'!B:B,'Download of SFDC Activation Rep'!S:S),"")} -> 35 | M24: {=iferror(XLOOKUP(A24,'Download of SFDC Activation Rep'!B:B,'Download of SFDC Activation Rep'!Z:Z)+150,"")} -> 46270 | N24: {=iferror(XLOOKUP(A24,'Download of SFDC Activation Rep'!B:B,'Download of SFDC Activation Rep'!Y:Y),"")} -> 46147 | U24: =IF(M24="", "", EOMONTH(M24, -5) + 1) -> 46143
G25: {=iferror(XLOOKUP(A25,'Download of SFDC Activation Rep'!B:B,'Download of SFDC Activation Rep'!H:H),"")} -> Active | H25: {=iferror(xlookup(A25,'Download of SFDC Activation Rep'!B:B,'Download of SFDC Activation Rep'!L:L),"")} | I25: =IF(or(G25="Active",H25="Active"),"Active","Not Active") -> Active | J25: {=iferror(XLOOKUP(A25,'Download of SFDC Activation Rep'!B:B,'Download of SFDC Activation Rep'!X:X),"")} -> Kate Olivares | K25: {=iferror(XLOOKUP(A25,'Download of SFDC Activation Rep'!B:B,'Download of SFDC Activation Rep'!C:C),"")} -> GK Truckline | L25: {=iferror(XLOOKUP(A25,'Download of SFDC Activation Rep'!B:B,'Download of SFDC Activation Rep'!S:S),"")} -> 461.94 | M25: {=iferror(XLOOKUP(A25,'Download of SFDC Activation Rep'!B:B,'Download of SFDC Activation Rep'!Z:Z)+150,"")} -> 46305 | N25: {=iferror(XLOOKUP(A25,'Download of SFDC Activation Rep'!B:B,'Download of SFDC Activation Rep'!Y:Y),"")} -> 46286 | U25: =IF(M25="", "", EOMONTH(M25, -5) + 1) -> 46174
G26: {=iferror(XLOOKUP(A26,'Download of SFDC Activation Rep'!B:B,'Download of SFDC Activation Rep'!H:H),"")} -> Active | H26: {=iferror(xlookup(A26,'Download of SFDC Activation Rep'!B:B,'Download of SFDC Activation Rep'!L:L),"")} | I26: =IF(or(G26="Active",H26="Active"),"Active","Not Active") -> Active | J26: {=iferror(XLOOKUP(A26,'Download of SFDC Activation Rep'!B:B,'Download of SFDC Activation Rep'!X:X),"")} -> Matthew Frost | K26: {=iferror(XLOOKUP(A26,'Download of SFDC Activation Rep'!B:B,'Download of SFDC Activation Rep'!C:C),"")} -> Protagenic Therapeutics, Inc. | L26: {=iferror(XLOOKUP(A26,'Download of SFDC Activation Rep'!B:B,'Download of SFDC Activation Rep'!S:S),"")} -> 147.7 | M26: {=iferror(XLOOKUP(A26,'Download of SFDC Activation Rep'!B:B,'Download of SFDC Activation Rep'!Z:Z)+150,"")} -> 46110 | N26: {=iferror(XLOOKUP(A26,'Download of SFDC Activation Rep'!B:B,'Download of SFDC Activation Rep'!Y:Y),"")} -> 46006 | U26: =IF(M26="", "", EOMONTH(M26, -5) + 1) -> 45962
G27: {=iferror(XLOOKUP(A27,'Download of SFDC Activation Rep'!B:B,'Download of SFDC Activation Rep'!H:H),"")} -> Active | H27: {=iferror(xlookup(A27,'Download of SFDC Activation Rep'!B:B,'Download of SFDC Activation Rep'!L:L),"")} -> Active | I27: =IF(or(G27="Active",H27="Active"),"Active","Not Active") -> Active | J27: {=iferror(XLOOKUP(A27,'Download of SFDC Activation Rep'!B:B,'Download of SFDC Activation Rep'!X:X),"")} -> Kate Olivares | K27: {=iferror(XLOOKUP(A27,'Download of SFDC Activation Rep'!B:B,'Download of SFDC Activation Rep'!C:C),"")} -> Rumford Stone, Inc | L27: {=iferror(XLOOKUP(A27,'Download of SFDC Activation Rep'!B:B,'Download of SFDC Activation Rep'!S:S),"")} -> 168.5 | M27: {=iferror(XLOOKUP(A27,'Download of SFDC Activation Rep'!B:B,'Download of SFDC Activation Rep'!Z:Z)+150,"")} -> 45947 | N27: {=iferror(XLOOKUP(A27,'Download of SFDC Activation Rep'!B:B,'Download of SFDC Activation Rep'!Y:Y),"")} -> 45797 | U27: =IF(M27="", "", EOMONTH(M27, -5) + 1) -> 45809
G28: {=iferror(XLOOKUP(A28,'Download of SFDC Activation Rep'!B:B,'Download of SFDC Activation Rep'!H:H),"")} -> Active | H28: {=iferror(xlookup(A28,'Download of SFDC Activation Rep'!B:B,'Download of SFDC Activation Rep'!L:L),"")} -> Active | I28: =IF(or(G28="Active",H28="Active"),"Active","Not Active") -> Active | J28: {=iferror(XLOOKUP(A28,'Download of SFDC Activation Rep'!B:B,'Download of SFDC Activation Rep'!X:X),"")} -> Matthew Frost | K28: {=iferror(XLOOKUP(A28,'Download of SFDC Activation Rep'!B:B,'Download of SFDC Activation Rep'!C:C),"")} -> Friendly Foods Inc | L28: {=iferror(XLOOKUP(A28,'Download of SFDC Activation Rep'!B:B,'Download of SFDC Activation Rep'!S:S),"")} -> 691.55 | M28: {=iferror(XLOOKUP(A28,'Download of SFDC Activation Rep'!B:B,'Download of SFDC Activation Rep'!Z:Z)+150,"")} -> 46157 | N28: {=iferror(XLOOKUP(A28,'Download of SFDC Activation Rep'!B:B,'Download of SFDC Activation Rep'!Y:Y),"")} -> 46021 | U28: =IF(M28="", "", EOMONTH(M28, -5) + 1) -> 46023
G29: {=iferror(XLOOKUP(A29,'Download of SFDC Activation Rep'!B:B,'Download of SFDC Activation Rep'!H:H),"")} -> Active | H29: {=iferror(xlookup(A29,'Download of SFDC Activation Rep'!B:B,'Download of SFDC Activation Rep'!L:L),"")} | I29: =IF(or(G29="Active",H29="Active"),"Active","Not Active") -> Active | J29: {=iferror(XLOOKUP(A29,'Download of SFDC Activation Rep'!B:B,'Download of SFDC Activation Rep'!X:X),"")} -> Matthew Frost | K29: {=iferror(XLOOKUP(A29,'Download of SFDC Activation Rep'!B:B,'Download of SFDC Activation Rep'!C:C),"")} -> Appellate Defenders, Inc. | L29: {=iferror(XLOOKUP(A29,'Download of SFDC Activation Rep'!B:B,'Download of SFDC Activation Rep'!S:S),"")} -> 107 | M29: {=iferror(XLOOKUP(A29,'Download of SFDC Activation Rep'!B:B,'Download of SFDC Activation Rep'!Z:Z)+150,"")} -> 46061 | N29: {=iferror(XLOOKUP(A29,'Download of SFDC Activation Rep'!B:B,'Download of SFDC Activation Rep'!Y:Y),"")} -> 45945 | U29: =IF(M29="", "", EOMONTH(M29, -5) + 1) -> 45931
G30: {=iferror(XLOOKUP(A30,'Download of SFDC Activation Rep'!B:B,'Download of SFDC Activation Rep'!H:H),"")} -> Active | H30: {=iferror(xlookup(A30,'Download of SFDC Activation Rep'!B:B,'Download of SFDC Activation Rep'!L:L),"")} | I30: =IF(or(G30="Active",H30="Active"),"Active","Not Active") -> Active | J30: {=iferror(XLOOKUP(A30,'Download of SFDC Activation Rep'!B:B,'Download of SFDC Activation Rep'!X:X),"")} -> Matthew Frost | K30: {=iferror(XLOOKUP(A30,'Download of SFDC Activation Rep'!B:B,'Download of SFDC Activation Rep'!C:C),"")} -> Herbert Law Group, LLC | L30: {=iferror(XLOOKUP(A30,'Download of SFDC Activation Rep'!B:B,'Download of SFDC Activation Rep'!S:S),"")} -> 375 | M30: {=iferror(XLOOKUP(A30,'Download of SFDC Activation Rep'!B:B,'Download of SFDC Activation Rep'!Z:Z)+150,"")} -> 46187 | N30: {=iferror(XLOOKUP(A30,'Download of SFDC Activation Rep'!B:B,'Download of SFDC Activation Rep'!Y:Y),"")} -> 46057 | U30: =IF(M30="", "", EOMONTH(M30, -5) + 1) -> 46054
G31: {=iferror(XLOOKUP(A31,'Download of SFDC Activation Rep'!B:B,'Download of SFDC Activation Rep'!H:H),"")} -> Active | H31: {=iferror(xlookup(A31,'Download of SFDC Activation Rep'!B:B,'Download of SFDC Activation Rep'!L:L),"")} | I31: =IF(or(G31="Active",H31="Active"),"Active","Not Active") -> Active | J31: {=iferror(XLOOKUP(A31,'Download of SFDC Activation Rep'!B:B,'Download of SFDC Activation Rep'!X:X),"")} -> Matthew Frost | K31: {=iferror(XLOOKUP(A31,'Download of SFDC Activation Rep'!B:B,'Download of SFDC Activation Rep'!C:C),"")} -> Cope Equities | L31: {=iferror(XLOOKUP(A31,'Download of SFDC Activation Rep'!B:B,'Download of SFDC Activation Rep'!S:S),"")} -> 0 | M31: {=iferror(XLOOKUP(A31,'Download of SFDC Activation Rep'!B:B,'Download of SFDC Activation Rep'!Z:Z)+150,"")} -> 46249 | N31: {=iferror(XLOOKUP(A31,'Download of SFDC Activation Rep'!B:B,'Download of SFDC Activation Rep'!Y:Y),"")} -> 46087 | U31: =IF(M31="", "", EOMONTH(M31, -5) + 1) -> 46113
... G172: {=iferror(XLOOKUP(A172,'Download of SFDC Activation Rep'!B:B,'Download of SFDC Activation Rep'!H:H),"")} | H172: {=iferror(xlookup(A172,'Download of SFDC Activation Rep'!B:B,'Download of SFDC Activation Rep'!L:L),"")} | I172: =IF(or(G172="Active",H172="Active"),"Active","Not Active") -> Not Active | J172: {=iferror(XLOOKUP(A172,'Download of SFDC Activation Rep'!B:B,'Download of SFDC Activation Rep'!X:X),"")} | K172: {=iferror(XLOOKUP(A172,'Download of SFDC Activation Rep'!B:B,'Download of SFDC Activation Rep'!C:C),"")} | L172: {=iferror(XLOOKUP(A172,'Download of SFDC Activation Rep'!B:B,'Download of SFDC Activation Rep'!S:S),"")} | M172: {=iferror(XLOOKUP(A172,'Download of SFDC Activation Rep'!B:B,'Download of SFDC Activation Rep'!Z:Z)+150,"")} | N172: {=iferror(XLOOKUP(A172,'Download of SFDC Activation Rep'!B:B,'Download of SFDC Activation Rep'!Y:Y),"")} | U172: =IF(M172="", "", EOMONTH(M172, -5) + 1)
G173: {=iferror(XLOOKUP(A173,'Download of SFDC Activation Rep'!B:B,'Download of SFDC Activation Rep'!H:H),"")} | H173: {=iferror(xlookup(A173,'Download of SFDC Activation Rep'!B:B,'Download of SFDC Activation Rep'!L:L),"")} | I173: =IF(or(G173="Active",H173="Active"),"Active","Not Active") -> Not Active | J173: {=iferror(XLOOKUP(A173,'Download of SFDC Activation Rep'!B:B,'Download of SFDC Activation Rep'!X:X),"")} | K173: {=iferror(XLOOKUP(A173,'Download of SFDC Activation Rep'!B:B,'Download of SFDC Activation Rep'!C:C),"")} | L173: {=iferror(XLOOKUP(A173,'Download of SFDC Activation Rep'!B:B,'Download of SFDC Activation Rep'!S:S),"")} | M173: {=iferror(XLOOKUP(A173,'Download of SFDC Activation Rep'!B:B,'Download of SFDC Activation Rep'!Z:Z)+150,"")} | N173: {=iferror(XLOOKUP(A173,'Download of SFDC Activation Rep'!B:B,'Download of SFDC Activation Rep'!Y:Y),"")}
G174: {=iferror(XLOOKUP(A174,'Download of SFDC Activation Rep'!B:B,'Download of SFDC Activation Rep'!H:H),"")} | H174: {=iferror(xlookup(A174,'Download of SFDC Activation Rep'!B:B,'Download of SFDC Activation Rep'!L:L),"")} | I174: =IF(or(G174="Active",H174="Active"),"Active","Not Active") -> Not Active | J174: {=iferror(XLOOKUP(A174,'Download of SFDC Activation Rep'!B:B,'Download of SFDC Activation Rep'!X:X),"")} | K174: {=iferror(XLOOKUP(A174,'Download of SFDC Activation Rep'!B:B,'Download of SFDC Activation Rep'!C:C),"")} | L174: {=iferror(XLOOKUP(A174,'Download of SFDC Activation Rep'!B:B,'Download of SFDC Activation Rep'!S:S),"")} | M174: {=iferror(XLOOKUP(A174,'Download of SFDC Activation Rep'!B:B,'Download of SFDC Activation Rep'!Z:Z)+150,"")} | N174: {=iferror(XLOOKUP(A174,'Download of SFDC Activation Rep'!B:B,'Download of SFDC Activation Rep'!Y:Y),"")}
G175: {=iferror(XLOOKUP(A175,'Download of SFDC Activation Rep'!B:B,'Download of SFDC Activation Rep'!H:H),"")} | H175: {=iferror(xlookup(A175,'Download of SFDC Activation Rep'!B:B,'Download of SFDC Activation Rep'!L:L),"")} | I175: =IF(or(G175="Active",H175="Active"),"Active","Not Active") -> Not Active | J175: {=iferror(XLOOKUP(A175,'Download of SFDC Activation Rep'!B:B,'Download of SFDC Activation Rep'!X:X),"")} | K175: {=iferror(XLOOKUP(A175,'Download of SFDC Activation Rep'!B:B,'Download of SFDC Activation Rep'!C:C),"")} | L175: {=iferror(XLOOKUP(A175,'Download of SFDC Activation Rep'!B:B,'Download of SFDC Activation Rep'!S:S),"")} | M175: {=iferror(XLOOKUP(A175,'Download of SFDC Activation Rep'!B:B,'Download of SFDC Activation Rep'!Z:Z)+150,"")} | N175: {=iferror(XLOOKUP(A175,'Download of SFDC Activation Rep'!B:B,'Download of SFDC Activation Rep'!Y:Y),"")}
G176: {=iferror(XLOOKUP(A176,'Download of SFDC Activation Rep'!B:B,'Download of SFDC Activation Rep'!H:H),"")} | H176: {=iferror(xlookup(A176,'Download of SFDC Activation Rep'!B:B,'Download of SFDC Activation Rep'!L:L),"")} | I176: =IF(or(G176="Active",H176="Active"),"Active","Not Active") -> Not Active | J176: {=iferror(XLOOKUP(A176,'Download of SFDC Activation Rep'!B:B,'Download of SFDC Activation Rep'!X:X),"")} | K176: {=iferror(XLOOKUP(A176,'Download of SFDC Activation Rep'!B:B,'Download of SFDC Activation Rep'!C:C),"")} | L176: {=iferror(XLOOKUP(A176,'Download of SFDC Activation Rep'!B:B,'Download of SFDC Activation Rep'!S:S),"")} | M176: {=iferror(XLOOKUP(A176,'Download of SFDC Activation Rep'!B:B,'Download of SFDC Activation Rep'!Z:Z)+150,"")} | N176: {=iferror(XLOOKUP(A176,'Download of SFDC Activation Rep'!B:B,'Download of SFDC Activation Rep'!Y:Y),"")}
G177: {=iferror(XLOOKUP(A177,'Download of SFDC Activation Rep'!B:B,'Download of SFDC Activation Rep'!H:H),"")} | H177: {=iferror(xlookup(A177,'Download of SFDC Activation Rep'!B:B,'Download of SFDC Activation Rep'!L:L),"")} | I177: =IF(or(G177="Active",H177="Active"),"Active","Not Active") -> Not Active | J177: {=iferror(XLOOKUP(A177,'Download of SFDC Activation Rep'!B:B,'Download of SFDC Activation Rep'!X:X),"")} | K177: {=iferror(XLOOKUP(A177,'Download of SFDC Activation Rep'!B:B,'Download of SFDC Activation Rep'!C:C),"")} | L177: {=iferror(XLOOKUP(A177,'Download of SFDC Activation Rep'!B:B,'Download of SFDC Activation Rep'!S:S),"")} | M177: {=iferror(XLOOKUP(A177,'Download of SFDC Activation Rep'!B:B,'Download of SFDC Activation Rep'!Z:Z)+150,"")} | N177: {=iferror(XLOOKUP(A177,'Download of SFDC Activation Rep'!B:B,'Download of SFDC Activation Rep'!Y:Y),"")}
G178: {=iferror(XLOOKUP(A178,'Download of SFDC Activation Rep'!B:B,'Download of SFDC Activation Rep'!H:H),"")} | H178: {=iferror(xlookup(A178,'Download of SFDC Activation Rep'!B:B,'Download of SFDC Activation Rep'!L:L),"")} | I178: =IF(or(G178="Active",H178="Active"),"Active","Not Active") -> Not Active | J178: {=iferror(XLOOKUP(A178,'Download of SFDC Activation Rep'!B:B,'Download of SFDC Activation Rep'!X:X),"")} | K178: {=iferror(XLOOKUP(A178,'Download of SFDC Activation Rep'!B:B,'Download of SFDC Activation Rep'!C:C),"")} | L178: {=iferror(XLOOKUP(A178,'Download of SFDC Activation Rep'!B:B,'Download of SFDC Activation Rep'!S:S),"")} | M178: {=iferror(XLOOKUP(A178,'Download of SFDC Activation Rep'!B:B,'Download of SFDC Activation Rep'!Z:Z)+150,"")} | N178: {=iferror(XLOOKUP(A178,'Download of SFDC Activation Rep'!B:B,'Download of SFDC Activation Rep'!Y:Y),"")}
G179: {=iferror(XLOOKUP(A179,'Download of SFDC Activation Rep'!B:B,'Download of SFDC Activation Rep'!H:H),"")} | H179: {=iferror(xlookup(A179,'Download of SFDC Activation Rep'!B:B,'Download of SFDC Activation Rep'!L:L),"")} | I179: =IF(or(G179="Active",H179="Active"),"Active","Not Active") -> Not Active | J179: {=iferror(XLOOKUP(A179,'Download of SFDC Activation Rep'!B:B,'Download of SFDC Activation Rep'!X:X),"")} | K179: {=iferror(XLOOKUP(A179,'Download of SFDC Activation Rep'!B:B,'Download of SFDC Activation Rep'!C:C),"")} | L179: {=iferror(XLOOKUP(A179,'Download of SFDC Activation Rep'!B:B,'Download of SFDC Activation Rep'!S:S),"")} | M179: {=iferror(XLOOKUP(A179,'Download of SFDC Activation Rep'!B:B,'Download of SFDC Activation Rep'!Z:Z)+150,"")} | N179: {=iferror(XLOOKUP(A179,'Download of SFDC Activation Rep'!B:B,'Download of SFDC Activation Rep'!Y:Y),"")}
G180: {=iferror(XLOOKUP(A180,'Download of SFDC Activation Rep'!B:B,'Download of SFDC Activation Rep'!H:H),"")} | H180: {=iferror(xlookup(A180,'Download of SFDC Activation Rep'!B:B,'Download of SFDC Activation Rep'!L:L),"")} | I180: =IF(or(G180="Active",H180="Active"),"Active","Not Active") -> Not Active | J180: {=iferror(XLOOKUP(A180,'Download of SFDC Activation Rep'!B:B,'Download of SFDC Activation Rep'!X:X),"")} | K180: {=iferror(XLOOKUP(A180,'Download of SFDC Activation Rep'!B:B,'Download of SFDC Activation Rep'!C:C),"")} | L180: {=iferror(XLOOKUP(A180,'Download of SFDC Activation Rep'!B:B,'Download of SFDC Activation Rep'!S:S),"")} | M180: {=iferror(XLOOKUP(A180,'Download of SFDC Activation Rep'!B:B,'Download of SFDC Activation Rep'!Z:Z)+150,"")} | N180: {=iferror(XLOOKUP(A180,'Download of SFDC Activation Rep'!B:B,'Download of SFDC Activation Rep'!Y:Y),"")}
...

Sheet Current Calendar Month Stats
F1: AP Status | G1: AR Status | H1: AP/AR Status | I1: Account Owner | J1: Account Name | K1: Opp Owner | L1: Create Date | M1: Total Orgs | N1: =COUNTIF(A2:A1000,">=0") -> 121 | P1: LAST DATA PULL: | Q1: 46201
F2: {=iferror(XLOOKUP(A2,'Download of SFDC Activation Rep'!B:B,'Download of SFDC Activation Rep'!H:H),"")} -> Active | G2: {=iferror(xlookup(A2,'Download of SFDC Activation Rep'!B:B,'Download of SFDC Activation Rep'!L:L),"")} | H2: =IF(or(F2="Active",G2="Active"),"Active","Not Active") -> Active | I2: {=XLOOKUP(A2,'Download of SFDC Activation Rep'!B:B,'Download of SFDC Activation Rep'!T:T)} -> 006VT00000sgdkK | J2: {=iferror(XLOOKUP(A2,'Download of SFDC Activation Rep'!B:B,'Download of SFDC Activation Rep'!C:C),"")} -> HTT Cardmax Company | K2: {=XLOOKUP(A2,'Download of SFDC Activation Rep'!B:B,'Download of SFDC Activation Rep'!X:X)} -> Arianna Modesti | L2: {=xlookup(A2,'Download of SFDC Activation Rep'!B:B,'Download of SFDC Activation Rep'!Z:Z)} -> 46197 | M2: Total Active Orgs | N2: =COUNTIF(H:H,"Active") -> 121 | O2: =SUMIFS('Redash Pull of Activated Org GP'!J:J,'Redash Pull of Activated Org GP'!B:B,"2025-10-01",'Redash Pull of Activated Org GP'!C:C,"<>4054136") -> 42
F3: {=iferror(XLOOKUP(A3,'Download of SFDC Activation Rep'!B:B,'Download of SFDC Activation Rep'!H:H),"")} -> Active | G3: {=iferror(xlookup(A3,'Download of SFDC Activation Rep'!B:B,'Download of SFDC Activation Rep'!L:L),"")} | H3: =IF(or(F3="Active",G3="Active"),"Active","Not Active") -> Active | I3: {=XLOOKUP(A3,'Download of SFDC Activation Rep'!B:B,'Download of SFDC Activation Rep'!T:T)} -> 006VT00000rNywD | J3: {=iferror(XLOOKUP(A3,'Download of SFDC Activation Rep'!B:B,'Download of SFDC Activation Rep'!C:C),"")} -> DataLinks LLC | K3: {=XLOOKUP(A3,'Download of SFDC Activation Rep'!B:B,'Download of SFDC Activation Rep'!X:X)} -> Arianna Modesti | L3: {=xlookup(A3,'Download of SFDC Activation Rep'!B:B,'Download of SFDC Activation Rep'!Z:Z)} -> 46170
F4: {=iferror(XLOOKUP(A4,'Download of SFDC Activation Rep'!B:B,'Download of SFDC Activation Rep'!H:H),"")} -> Active | G4: {=iferror(xlookup(A4,'Download of SFDC Activation Rep'!B:B,'Download of SFDC Activation Rep'!L:L),"")} | H4: =IF(or(F4="Active",G4="Active"),"Active","Not Active") -> Active | I4: {=XLOOKUP(A4,'Download of SFDC Activation Rep'!B:B,'Download of SFDC Activation Rep'!T:T)} -> 006UU00000Og7FN | J4: {=iferror(XLOOKUP(A4,'Download of SFDC Activation Rep'!B:B,'Download of SFDC Activation Rep'!C:C),"")} -> Solutions Group International, Inc. | K4: {=XLOOKUP(A4,'Download of SFDC Activation Rep'!B:B,'Download of SFDC Activation Rep'!X:X)} -> Matthew Frost | L4: {=xlookup(A4,'Download of SFDC Activation Rep'!B:B,'Download of SFDC Activation Rep'!Z:Z)} -> 46028 | M4: Avg TPV per Org | N4: =N15/N2 -> 130241.22
F5: {=iferror(XLOOKUP(A5,'Download of SFDC Activation Rep'!B:B,'Download of SFDC Activation Rep'!H:H),"")} -> Active | G5: {=iferror(xlookup(A5,'Download of SFDC Activation Rep'!B:B,'Download of SFDC Activation Rep'!L:L),"")} | H5: =IF(or(F5="Active",G5="Active"),"Active","Not Active") -> Active | I5: {=XLOOKUP(A5,'Download of SFDC Activation Rep'!B:B,'Download of SFDC Activation Rep'!T:T)} -> 006UU00000LzrZs | J5: {=iferror(XLOOKUP(A5,'Download of SFDC Activation Rep'!B:B,'Download of SFDC Activation Rep'!C:C),"")} -> Net Conversion | K5: {=XLOOKUP(A5,'Download of SFDC Activation Rep'!B:B,'Download of SFDC Activation Rep'!X:X)} -> Kate Olivares | L5: {=xlookup(A5,'Download of SFDC Activation Rep'!B:B,'Download of SFDC Activation Rep'!Z:Z)} -> 45831
F6: {=iferror(XLOOKUP(A6,'Download of SFDC Activation Rep'!B:B,'Download of SFDC Activation Rep'!H:H),"")} -> Active | G6: {=iferror(xlookup(A6,'Download of SFDC Activation Rep'!B:B,'Download of SFDC Activation Rep'!L:L),"")} | H6: =IF(or(F6="Active",G6="Active"),"Active","Not Active") -> Active | I6: {=XLOOKUP(A6,'Download of SFDC Activation Rep'!B:B,'Download of SFDC Activation Rep'!T:T)} -> 006VT00000pom8v | J6: {=iferror(XLOOKUP(A6,'Download of SFDC Activation Rep'!B:B,'Download of SFDC Activation Rep'!C:C),"")} -> Kloris LLC | K6: {=XLOOKUP(A6,'Download of SFDC Activation Rep'!B:B,'Download of SFDC Activation Rep'!X:X)} -> Arianna Modesti | L6: {=xlookup(A6,'Download of SFDC Activation Rep'!B:B,'Download of SFDC Activation Rep'!Z:Z)} -> 46136 | M6: Avg GP per Org | N6: =N13/N2 -> 227.2066
F7: {=iferror(XLOOKUP(A7,'Download of SFDC Activation Rep'!B:B,'Download of SFDC Activation Rep'!H:H),"")} -> Active | G7: {=iferror(xlookup(A7,'Download of SFDC Activation Rep'!B:B,'Download of SFDC Activation Rep'!L:L),"")} | H7: =IF(or(F7="Active",G7="Active"),"Active","Not Active") -> Active | I7: {=XLOOKUP(A7,'Download of SFDC Activation Rep'!B:B,'Download of SFDC Activation Rep'!T:T)} -> 006VT00000sgdkF | J7: {=iferror(XLOOKUP(A7,'Download of SFDC Activation Rep'!B:B,'Download of SFDC Activation Rep'!C:C),"")} -> Naz Apparel | K7: {=XLOOKUP(A7,'Download of SFDC Activation Rep'!B:B,'Download of SFDC Activation Rep'!X:X)} -> Arianna Modesti | L7: {=xlookup(A7,'Download of SFDC Activation Rep'!B:B,'Download of SFDC Activation Rep'!Z:Z)} -> 46197
F8: {=iferror(XLOOKUP(A8,'Download of SFDC Activation Rep'!B:B,'Download of SFDC Activation Rep'!H:H),"")} -> Active | G8: {=iferror(xlookup(A8,'Download of SFDC Activation Rep'!B:B,'Download of SFDC Activation Rep'!L:L),"")} | H8: =IF(or(F8="Active",G8="Active"),"Active","Not Active") -> Active | I8: {=XLOOKUP(A8,'Download of SFDC Activation Rep'!B:B,'Download of SFDC Activation Rep'!T:T)} -> 006UU00000Lzmjj | J8: {=iferror(XLOOKUP(A8,'Download of SFDC Activation Rep'!B:B,'Download of SFDC Activation Rep'!C:C),"")} -> Hendersonville Community Co-Op | K8: {=XLOOKUP(A8,'Download of SFDC Activation Rep'!B:B,'Download of SFDC Activation Rep'!X:X)} -> Matthew Frost | L8: {=xlookup(A8,'Download of SFDC Activation Rep'!B:B,'Download of SFDC Activation Rep'!Z:Z)} -> 45891
F9: {=iferror(XLOOKUP(A9,'Download of SFDC Activation Rep'!B:B,'Download of SFDC Activation Rep'!H:H),"")} -> Active | G9: {=iferror(xlookup(A9,'Download of SFDC Activation Rep'!B:B,'Download of SFDC Activation Rep'!L:L),"")} -> Active | H9: =IF(or(F9="Active",G9="Active"),"Active","Not Active") -> Active | I9: {=XLOOKUP(A9,'Download of SFDC Activation Rep'!B:B,'Download of SFDC Activation Rep'!T:T)} -> 006UU00000OgQGQ | J9: {=iferror(XLOOKUP(A9,'Download of SFDC Activation Rep'!B:B,'Download of SFDC Activation Rep'!C:C),"")} -> Scale Foundations Inc. | K9: {=XLOOKUP(A9,'Download of SFDC Activation Rep'!B:B,'Download of SFDC Activation Rep'!X:X)} -> Matthew Frost | L9: {=xlookup(A9,'Download of SFDC Activation Rep'!B:B,'Download of SFDC Activation Rep'!Z:Z)} -> 46028
F10: {=iferror(XLOOKUP(A10,'Download of SFDC Activation Rep'!B:B,'Download of SFDC Activation Rep'!H:H),"")} -> Active | G10: {=iferror(xlookup(A10,'Download of SFDC Activation Rep'!B:B,'Download of SFDC Activation Rep'!L:L),"")} | H10: =IF(or(F10="Active",G10="Active"),"Active","Not Active") -> Active | I10: {=XLOOKUP(A10,'Download of SFDC Activation Rep'!B:B,'Download of SFDC Activation Rep'!T:T)} -> 006VT00000niYeT | J10: {=iferror(XLOOKUP(A10,'Download of SFDC Activation Rep'!B:B,'Download of SFDC Activation Rep'!C:C),"")} -> Brian Schmidt Builder | K10: {=XLOOKUP(A10,'Download of SFDC Activation Rep'!B:B,'Download of SFDC Activation Rep'!X:X)} -> Arianna Modesti | L10: {=xlookup(A10,'Download of SFDC Activation Rep'!B:B,'Download of SFDC Activation Rep'!Z:Z)} -> 46092
F11: {=iferror(XLOOKUP(A11,'Download of SFDC Activation Rep'!B:B,'Download of SFDC Activation Rep'!H:H),"")} -> Active | G11: {=iferror(xlookup(A11,'Download of SFDC Activation Rep'!B:B,'Download of SFDC Activation Rep'!L:L),"")} | H11: =IF(or(F11="Active",G11="Active"),"Active","Not Active") -> Active | I11: {=XLOOKUP(A11,'Download of SFDC Activation Rep'!B:B,'Download of SFDC Activation Rep'!T:T)} -> 006UU00000LzrZl | J11: {=iferror(XLOOKUP(A11,'Download of SFDC Activation Rep'!B:B,'Download of SFDC Activation Rep'!C:C),"")} -> Toland Construction - MO
F12: {=iferror(XLOOKUP(A12,'Download of SFDC Activation Rep'!B:B,'Download of SFDC Activation Rep'!H:H),"")} -> Active | G12: {=iferror(xlookup(A12,'Download of SFDC Activation Rep'!B:B,'Download of SFDC Activation Rep'!L:L),"")} | H12: =IF(or(F12="Active",G12="Active"),"Active","Not Active") -> Active | I12: {=XLOOKUP(A12,'Download of SFDC Activation Rep'!B:B,'Download of SFDC Activation Rep'!T:T)} -> 006VT00000qfNVl | J12: {=iferror(XLOOKUP(A12,'Download of SFDC Activation Rep'!B:B,'Download of SFDC Activation Rep'!C:C),"")} -> GK Truckline | K12: {=XLOOKUP(A12,'Download of SFDC Activation Rep'!B:B,'Download of SFDC Activation Rep'!X:X)} -> Kate Olivares | L12: {=xlookup(A12,'Download of SFDC Activation Rep'!B:B,'Download of SFDC Activation Rep'!Z:Z)} -> 46155
F13: {=iferror(XLOOKUP(A13,'Download of SFDC Activation Rep'!B:B,'Download of SFDC Activation Rep'!H:H),"")} -> Active | G13: {=iferror(xlookup(A13,'Download of SFDC Activation Rep'!B:B,'Download of SFDC Activation Rep'!L:L),"")} | H13: =IF(or(F13="Active",G13="Active"),"Active","Not Active") -> Active | I13: {=XLOOKUP(A13,'Download of SFDC Activation Rep'!B:B,'Download of SFDC Activation Rep'!T:T)} -> 006UU00000O1KbZ | J13: {=iferror(XLOOKUP(A13,'Download of SFDC Activation Rep'!B:B,'Download of SFDC Activation Rep'!C:C),"")} -> MJDII Architects, Inc. | K13: {=XLOOKUP(A13,'Download of SFDC Activation Rep'!B:B,'Download of SFDC Activation Rep'!X:X)} -> Matthew Frost | L13: {=xlookup(A13,'Download of SFDC Activation Rep'!B:B,'Download of SFDC Activation Rep'!Z:Z)} -> 46007 | M13: Total GP Generated | N13: =SUM(B:B) -> 27491.998
F14: {=iferror(XLOOKUP(A14,'Download of SFDC Activation Rep'!B:B,'Download of SFDC Activation Rep'!H:H),"")} -> Active | G14: {=iferror(xlookup(A14,'Download of SFDC Activation Rep'!B:B,'Download of SFDC Activation Rep'!L:L),"")} | H14: =IF(or(F14="Active",G14="Active"),"Active","Not Active") -> Active | I14: {=XLOOKUP(A14,'Download of SFDC Activation Rep'!B:B,'Download of SFDC Activation Rep'!T:T)} -> 006UU00000MQpnD | J14: {=iferror(XLOOKUP(A14,'Download of SFDC Activation Rep'!B:B,'Download of SFDC Activation Rep'!C:C),"")} -> Expert Semiconductor Technology, inc | K14: {=XLOOKUP(A14,'Download of SFDC Activation Rep'!B:B,'Download of SFDC Activation Rep'!X:X)} -> Kate Olivares | L14: {=xlookup(A14,'Download of SFDC Activation Rep'!B:B,'Download of SFDC Activation Rep'!Z:Z)} -> 45818
F15: {=iferror(XLOOKUP(A15,'Download of SFDC Activation Rep'!B:B,'Download of SFDC Activation Rep'!H:H),"")} -> Active | G15: {=iferror(xlookup(A15,'Download of SFDC Activation Rep'!B:B,'Download of SFDC Activation Rep'!L:L),"")} | H15: =IF(or(F15="Active",G15="Active"),"Active","Not Active") -> Active | I15: {=XLOOKUP(A15,'Download of SFDC Activation Rep'!B:B,'Download of SFDC Activation Rep'!T:T)} -> 006VT00000oiGKQ | J15: {=iferror(XLOOKUP(A15,'Download of SFDC Activation Rep'!B:B,'Download of SFDC Activation Rep'!C:C),"")} -> Landa Cleary Travel Co. Inc. D.B.A. Mater Dei Tours | K15: {=XLOOKUP(A15,'Download of SFDC Activation Rep'!B:B,'Download of SFDC Activation Rep'!X:X)} -> Arianna Modesti | L15: {=xlookup(A15,'Download of SFDC Activation Rep'!B:B,'Download of SFDC Activation Rep'!Z:Z)} -> 46113 | M15: Total TPV Generated | N15: =SUM(D:D) -> 15759187
F16: {=iferror(XLOOKUP(A16,'Download of SFDC Activation Rep'!B:B,'Download of SFDC Activation Rep'!H:H),"")} -> Active | G16: {=iferror(xlookup(A16,'Download of SFDC Activation Rep'!B:B,'Download of SFDC Activation Rep'!L:L),"")} | H16: =IF(or(F16="Active",G16="Active"),"Active","Not Active") -> Active | I16: {=XLOOKUP(A16,'Download of SFDC Activation Rep'!B:B,'Download of SFDC Activation Rep'!T:T)} -> 006UU00000MU72b | J16: {=iferror(XLOOKUP(A16,'Download of SFDC Activation Rep'!B:B,'Download of SFDC Activation Rep'!C:C),"")} -> Buescher Ranch | K16: {=XLOOKUP(A16,'Download of SFDC Activation Rep'!B:B,'Download of SFDC Activation Rep'!X:X)} -> Kate Olivares | L16: {=xlookup(A16,'Download of SFDC Activation Rep'!B:B,'Download of SFDC Activation Rep'!Z:Z)} -> 45966
F17: {=iferror(XLOOKUP(A17,'Download of SFDC Activation Rep'!B:B,'Download of SFDC Activation Rep'!H:H),"")} -> Active | G17: {=iferror(xlookup(A17,'Download of SFDC Activation Rep'!B:B,'Download of SFDC Activation Rep'!L:L),"")} | H17: =IF(or(F17="Active",G17="Active"),"Active","Not Active") -> Active | I17: {=XLOOKUP(A17,'Download of SFDC Activation Rep'!B:B,'Download of SFDC Activation Rep'!T:T)} -> 006UU00000OcWHB | J17: {=iferror(XLOOKUP(A17,'Download of SFDC Activation Rep'!B:B,'Download of SFDC Activation Rep'!C:C),"")} -> Kenneth Adam Designs | K17: {=XLOOKUP(A17,'Download of SFDC Activation Rep'!B:B,'Download of SFDC Activation Rep'!X:X)} -> Matthew Frost | L17: {=xlookup(A17,'Download of SFDC Activation Rep'!B:B,'Download of SFDC Activation Rep'!Z:Z)} -> 46027
F18: {=iferror(XLOOKUP(A18,'Download of SFDC Activation Rep'!B:B,'Download of SFDC Activation Rep'!H:H),"")} -> Active | G18: {=iferror(xlookup(A18,'Download of SFDC Activation Rep'!B:B,'Download of SFDC Activation Rep'!L:L),"")} | H18: =IF(or(F18="Active",G18="Active"),"Active","Not Active") -> Active | I18: {=XLOOKUP(A18,'Download of SFDC Activation Rep'!B:B,'Download of SFDC Activation Rep'!T:T)} -> 006UU00000KruBr | J18: {=iferror(XLOOKUP(A18,'Download of SFDC Activation Rep'!B:B,'Download of SFDC Activation Rep'!C:C),"")} -> megg mining llc | K18: {=XLOOKUP(A18,'Download of SFDC Activation Rep'!B:B,'Download of SFDC Activation Rep'!X:X)} -> Rudy Maestas | L18: {=xlookup(A18,'Download of SFDC Activation Rep'!B:B,'Download of SFDC Activation Rep'!Z:Z)} -> 45924 | M18: Median TPV per Org per Month | N18: =MEDIAN(D:D) -> 27018.47
F19: {=iferror(XLOOKUP(A19,'Download of SFDC Activation Rep'!B:B,'Download of SFDC Activation Rep'!H:H),"")} -> Active | G19: {=iferror(xlookup(A19,'Download of SFDC Activation Rep'!B:B,'Download of SFDC Activation Rep'!L:L),"")} | H19: =IF(or(F19="Active",G19="Active"),"Active","Not Active") -> Active | I19: {=XLOOKUP(A19,'Download of SFDC Activation Rep'!B:B,'Download of SFDC Activation Rep'!T:T)} -> 006UU00000MQpnP | J19: {=iferror(XLOOKUP(A19,'Download of SFDC Activation Rep'!B:B,'Download of SFDC Activation Rep'!C:C),"")} -> United Home Care LLC | K19: {=XLOOKUP(A19,'Download of SFDC Activation Rep'!B:B,'Download of SFDC Activation Rep'!X:X)} -> Kate Olivares | L19: {=xlookup(A19,'Download of SFDC Activation Rep'!B:B,'Download of SFDC Activation Rep'!Z:Z)} -> 45839 | M19: Median Monthly GP per Org | N19: =MEDIAN(B:B) -> 60.1
F20: {=iferror(XLOOKUP(A20,'Download of SFDC Activation Rep'!B:B,'Download of SFDC Activation Rep'!H:H),"")} -> Active | G20: {=iferror(xlookup(A20,'Download of SFDC Activation Rep'!B:B,'Download of SFDC Activation Rep'!L:L),"")} | H20: =IF(or(F20="Active",G20="Active"),"Active","Not Active") -> Active | I20: {=XLOOKUP(A20,'Download of SFDC Activation Rep'!B:B,'Download of SFDC Activation Rep'!T:T)} -> 006VT00000qes29 | J20: {=iferror(XLOOKUP(A20,'Download of SFDC Activation Rep'!B:B,'Download of SFDC Activation Rep'!C:C),"")} -> Temporary Assistance Guru, Inc | K20: {=XLOOKUP(A20,'Download of SFDC Activation Rep'!B:B,'Download of SFDC Activation Rep'!X:X)} -> Arianna Modesti | L20: {=xlookup(A20,'Download of SFDC Activation Rep'!B:B,'Download of SFDC Activation Rep'!Z:Z)} -> 46155
F21: {=iferror(XLOOKUP(A21,'Download of SFDC Activation Rep'!B:B,'Download of SFDC Activation Rep'!H:H),"")} -> Active | G21: {=iferror(xlookup(A21,'Download of SFDC Activation Rep'!B:B,'Download of SFDC Activation Rep'!L:L),"")} | H21: =IF(or(F21="Active",G21="Active"),"Active","Not Active") -> Active | I21: {=XLOOKUP(A21,'Download of SFDC Activation Rep'!B:B,'Download of SFDC Activation Rep'!T:T)} -> 006UU00000MGsar | J21: {=iferror(XLOOKUP(A21,'Download of SFDC Activation Rep'!B:B,'Download of SFDC Activation Rep'!C:C),"")} -> Protagenic Therapeutics, Inc. | K21: {=XLOOKUP(A21,'Download of SFDC Activation Rep'!B:B,'Download of SFDC Activation Rep'!X:X)} -> Matthew Frost | L21: {=xlookup(A21,'Download of SFDC Activation Rep'!B:B,'Download of SFDC Activation Rep'!Z:Z)} -> 45960
F22: {=iferror(XLOOKUP(A22,'Download of SFDC Activation Rep'!B:B,'Download of SFDC Activation Rep'!H:H),"")} -> Inactive | G22: {=iferror(xlookup(A22,'Download of SFDC Activation Rep'!B:B,'Download of SFDC Activation Rep'!L:L),"")} -> Active | H22: =IF(or(F22="Active",G22="Active"),"Active","Not Active") -> Active | I22: {=XLOOKUP(A22,'Download of SFDC Activation Rep'!B:B,'Download of SFDC Activation Rep'!T:T)} -> 006VT00000sgdkD | J22: {=iferror(XLOOKUP(A22,'Download of SFDC Activation Rep'!B:B,'Download of SFDC Activation Rep'!C:C),"")} -> lanier welding products | K22: {=XLOOKUP(A22,'Download of SFDC Activation Rep'!B:B,'Download of SFDC Activation Rep'!X:X)} -> Arianna Modesti | L22: {=xlookup(A22,'Download of SFDC Activation Rep'!B:B,'Download of SFDC Activation Rep'!Z:Z)} -> 46197
F23: {=iferror(XLOOKUP(A23,'Download of SFDC Activation Rep'!B:B,'Download of SFDC Activation Rep'!H:H),"")} -> Active | G23: {=iferror(xlookup(A23,'Download of SFDC Activation Rep'!B:B,'Download of SFDC Activation Rep'!L:L),"")} -> Active | H23: =IF(or(F23="Active",G23="Active"),"Active","Not Active") -> Active | I23: {=XLOOKUP(A23,'Download of SFDC Activation Rep'!B:B,'Download of SFDC Activation Rep'!T:T)} -> 006UU00000LzrZk | J23: {=iferror(XLOOKUP(A23,'Download of SFDC Activation Rep'!B:B,'Download of SFDC Activation Rep'!C:C),"")} -> Rumford Stone, Inc | K23: {=XLOOKUP(A23,'Download of SFDC Activation Rep'!B:B,'Download of SFDC Activation Rep'!X:X)} -> Kate Olivares | L23: {=xlookup(A23,'Download of SFDC Activation Rep'!B:B,'Download of SFDC Activation Rep'!Z:Z)} -> 45797
F24: {=iferror(XLOOKUP(A24,'Download of SFDC Activation Rep'!B:B,'Download of SFDC Activation Rep'!H:H),"")} -> Active | G24: {=iferror(xlookup(A24,'Download of SFDC Activation Rep'!B:B,'Download of SFDC Activation Rep'!L:L),"")} | H24: =IF(or(F24="Active",G24="Active"),"Active","Not Active") -> Active | I24: {=XLOOKUP(A24,'Download of SFDC Activation Rep'!B:B,'Download of SFDC Activation Rep'!T:T)} -> 006UU00000LzrZp | J24: {=iferror(XLOOKUP(A24,'Download of SFDC Activation Rep'!B:B,'Download of SFDC Activation Rep'!C:C),"")} -> Liberty Orchards LLC | K24: {=XLOOKUP(A24,'Download of SFDC Activation Rep'!B:B,'Download of SFDC Activation Rep'!X:X)} -> Kate Olivares | L24: {=xlookup(A24,'Download of SFDC Activation Rep'!B:B,'Download of SFDC Activation Rep'!Z:Z)} -> 45856
F25: {=iferror(XLOOKUP(A25,'Download of SFDC Activation Rep'!B:B,'Download of SFDC Activation Rep'!H:H),"")} -> Active | G25: {=iferror(xlookup(A25,'Download of SFDC Activation Rep'!B:B,'Download of SFDC Activation Rep'!L:L),"")} | H25: =IF(or(F25="Active",G25="Active"),"Active","Not Active") -> Active | I25: {=XLOOKUP(A25,'Download of SFDC Activation Rep'!B:B,'Download of SFDC Activation Rep'!T:T)} -> 006UU00000LzrZn | J25: {=iferror(XLOOKUP(A25,'Download of SFDC Activation Rep'!B:B,'Download of SFDC Activation Rep'!C:C),"")} -> CRUSHS | K25: {=XLOOKUP(A25,'Download of SFDC Activation Rep'!B:B,'Download of SFDC Activation Rep'!X:X)} -> Matthew Frost | L25: {=xlookup(A25,'Download of SFDC Activation Rep'!B:B,'Download of SFDC Activation Rep'!Z:Z)} -> 45890
F26: {=iferror(XLOOKUP(A26,'Download of SFDC Activation Rep'!B:B,'Download of SFDC Activation Rep'!H:H),"")} -> Active | G26: {=iferror(xlookup(A26,'Download of SFDC Activation Rep'!B:B,'Download of SFDC Activation Rep'!L:L),"")} -> Active | H26: =IF(or(F26="Active",G26="Active"),"Active","Not Active") -> Active | I26: {=XLOOKUP(A26,'Download of SFDC Activation Rep'!B:B,'Download of SFDC Activation Rep'!T:T)} -> 006UU00000O1zBi | J26: {=iferror(XLOOKUP(A26,'Download of SFDC Activation Rep'!B:B,'Download of SFDC Activation Rep'!C:C),"")} -> Friendly Foods Inc
